Workbook

Sheet Pokédex
A1: Dex Number | B1: Name | C1: =Changed!C1 -> Type 1 | D1: =Changed!D1 -> Type 2 | E1: =Changed!E1 -> Ability 1 | F1: =Changed!F1 -> Ability 2 | G1: =Changed!G1 -> Total | H1: =Changed!H1 -> HP | I1: =Changed!I1 -> Attack | J1: =Changed!J1 -> Defense | ... M1: =Changed!M1 -> Speed | N1: Total Diff | O1: Notes | P1: Originally from Pokemon DB
A2: 1 | B2: Bulbasaur | C2: =IF(Changed!C2<>"", Changed!C2, "") -> Grass | D2: =IF(Changed!D2<>"", Changed!D2, "") -> Poison | E2: =IF(Changed!E2<>"", Changed!E2, "") -> Chlorophyll | F2: =IF(Changed!F2<>"", Changed!F2, "") -> Grassy Surge | G2: {=INDEX(Changed!$G:$G,ROW())&IF(Changed!$G2>Base!$G2,"↑",IF(Changed!$G2<Base!$G2," ↓",""))} -> 318 | H2: {=INDEX(Changed!$H:$H,ROW())&IF(Changed!$H2>Base!$H2,"↑",IF(Changed!$H2<Base!$H2," ↓",""))} -> 45 | I2: {=INDEX(Changed!$I:$I,ROW())&IF(Changed!$I2>Base!$I2,"↑",IF(Changed!$I2<Base!$I2," ↓",""))} -> 49 | J2: {=INDEX(Changed!$J:$J,ROW())&IF(Changed!$J2>Base!$J2,"↑",IF(Changed!$J2<Base!$J2," ↓",""))} -> 49 | K2: {=INDEX(Changed!$K:$K,ROW())&IF(Changed!$K2>Base!$K2,"↑",IF(Changed!$K2<Base!$K2," ↓",""))} -> 65 | L2: {=INDEX(Changed!$L:$L,ROW())&IF(Changed!$L2>Base!$L2,"↑",IF(Changed!$L2<Base!$L2," ↓",""))} -> 65 | M2: {=INDEX(Changed!$M:$M,ROW())&IF(Changed!$M2>Base!$M2,"↑",IF(Changed!$M2<Base!$M2," ↓",""))} -> 45 | N2: =Changed!G2-Base!G2 -> 0
A3: 2 | B3: Ivysaur | C3: =IF(Changed!C3<>"", Changed!C3, "") -> Grass | D3: =IF(Changed!D3<>"", Changed!D3, "") -> Poison | E3: =IF(Changed!E3<>"", Changed!E3, "") -> Chlorophyll | F3: =IF(Changed!F3<>"", Changed!F3, "") -> Grassy Surge | G3: {=INDEX(Changed!$G:$G,ROW())&IF(Changed!$G3>Base!$G3,"↑",IF(Changed!$G3<Base!$G3," ↓",""))} -> 405 | H3: {=INDEX(Changed!$H:$H,ROW())&IF(Changed!$H3>Base!$H3,"↑",IF(Changed!$H3<Base!$H3," ↓",""))} -> 60 | I3: {=INDEX(Changed!$I:$I,ROW())&IF(Changed!$I3>Base!$I3,"↑",IF(Changed!$I3<Base!$I3," ↓",""))} -> 62 | J3: {=INDEX(Changed!$J:$J,ROW())&IF(Changed!$J3>Base!$J3,"↑",IF(Changed!$J3<Base!$J3," ↓",""))} -> 63 | K3: {=INDEX(Changed!$K:$K,ROW())&IF(Changed!$K3>Base!$K3,"↑",IF(Changed!$K3<Base!$K3," ↓",""))} -> 80 | L3: {=INDEX(Changed!$L:$L,ROW())&IF(Changed!$L3>Base!$L3,"↑",IF(Changed!$L3<Base!$L3," ↓",""))} -> 80 | M3: {=INDEX(Changed!$M:$M,ROW())&IF(Changed!$M3>Base!$M3,"↑",IF(Changed!$M3<Base!$M3," ↓",""))} -> 60 | N3: =Changed!G3-Base!G3 -> 0 | P3: You will only have access to the regional dex during the game. The regional dex contains all Pokémon.
A4: 3 | B4: Venusaur | C4: =IF(Changed!C4<>"", Changed!C4, "") -> Grass | D4: =IF(Changed!D4<>"", Changed!D4, "") -> Poison | E4: =IF(Changed!E4<>"", Changed!E4, "") -> Chlorophyll | F4: =IF(Changed!F4<>"", Changed!F4, "") -> Grassy Surge | G4: {=INDEX(Changed!$G:$G,ROW())&IF(Changed!$G4>Base!$G4,"↑",IF(Changed!$G4<Base!$G4," ↓",""))} -> 525 | H4: {=INDEX(Changed!$H:$H,ROW())&IF(Changed!$H4>Base!$H4,"↑",IF(Changed!$H4<Base!$H4," ↓",""))} -> 80 | I4: {=INDEX(Changed!$I:$I,ROW())&IF(Changed!$I4>Base!$I4,"↑",IF(Changed!$I4<Base!$I4," ↓",""))} -> 82 | J4: {=INDEX(Changed!$J:$J,ROW())&IF(Changed!$J4>Base!$J4,"↑",IF(Changed!$J4<Base!$J4," ↓",""))} -> 83 | K4: {=INDEX(Changed!$K:$K,ROW())&IF(Changed!$K4>Base!$K4,"↑",IF(Changed!$K4<Base!$K4," ↓",""))} -> 100 | L4: {=INDEX(Changed!$L:$L,ROW())&IF(Changed!$L4>Base!$L4,"↑",IF(Changed!$L4<Base!$L4," ↓",""))} -> 100 | M4: {=INDEX(Changed!$M:$M,ROW())&IF(Changed!$M4>Base!$M4,"↑",IF(Changed!$M4<Base!$M4," ↓",""))} -> 80 | N4: =Changed!G4-Base!G4 -> 0 | P4: The regional dex will follow the national dex order bar for the change stated below.
A5: 4 | B5: Charmander | C5: =IF(Changed!C5<>"", Changed!C5, "") -> Fire | D5: =IF(Changed!D5<>"", Changed!D5, "") | E5: =IF(Changed!E5<>"", Changed!E5, "") -> Blaze | F5: =IF(Changed!F5<>"", Changed!F5, "") -> Solar Power | G5: {=INDEX(Changed!$G:$G,ROW())&IF(Changed!$G5>Base!$G5,"↑",IF(Changed!$G5<Base!$G5," ↓",""))} -> 309 | H5: {=INDEX(Changed!$H:$H,ROW())&IF(Changed!$H5>Base!$H5,"↑",IF(Changed!$H5<Base!$H5," ↓",""))} -> 39 | I5: {=INDEX(Changed!$I:$I,ROW())&IF(Changed!$I5>Base!$I5,"↑",IF(Changed!$I5<Base!$I5," ↓",""))} -> 52 | J5: {=INDEX(Changed!$J:$J,ROW())&IF(Changed!$J5>Base!$J5,"↑",IF(Changed!$J5<Base!$J5," ↓",""))} -> 43 | K5: {=INDEX(Changed!$K:$K,ROW())&IF(Changed!$K5>Base!$K5,"↑",IF(Changed!$K5<Base!$K5," ↓",""))} -> 60 | L5: {=INDEX(Changed!$L:$L,ROW())&IF(Changed!$L5>Base!$L5,"↑",IF(Changed!$L5<Base!$L5," ↓",""))} -> 50 | M5: {=INDEX(Changed!$M:$M,ROW())&IF(Changed!$M5>Base!$M5,"↑",IF(Changed!$M5<Base!$M5," ↓",""))} -> 65 | N5: =Changed!G5-Base!G5 -> 0 | P5: Dex entries have been moved around to match the evolutions in the game. E.g. Pichu before Pikachu, Espeon after Flareon
A6: 5 | B6: Charmeleon | C6: =IF(Changed!C6<>"", Changed!C6, "") -> Fire | D6: =IF(Changed!D6<>"", Changed!D6, "") | E6: =IF(Changed!E6<>"", Changed!E6, "") -> Blaze | F6: =IF(Changed!F6<>"", Changed!F6, "") -> Solar Power | G6: {=INDEX(Changed!$G:$G,ROW())&IF(Changed!$G6>Base!$G6,"↑",IF(Changed!$G6<Base!$G6," ↓",""))} -> 405 | H6: {=INDEX(Changed!$H:$H,ROW())&IF(Changed!$H6>Base!$H6,"↑",IF(Changed!$H6<Base!$H6," ↓",""))} -> 58 | I6: {=INDEX(Changed!$I:$I,ROW())&IF(Changed!$I6>Base!$I6,"↑",IF(Changed!$I6<Base!$I6," ↓",""))} -> 64 | J6: {=INDEX(Changed!$J:$J,ROW())&IF(Changed!$J6>Base!$J6,"↑",IF(Changed!$J6<Base!$J6," ↓",""))} -> 58 | K6: {=INDEX(Changed!$K:$K,ROW())&IF(Changed!$K6>Base!$K6,"↑",IF(Changed!$K6<Base!$K6," ↓",""))} -> 80 | L6: {=INDEX(Changed!$L:$L,ROW())&IF(Changed!$L6>Base!$L6,"↑",IF(Changed!$L6<Base!$L6," ↓",""))} -> 65 | M6: {=INDEX(Changed!$M:$M,ROW())&IF(Changed!$M6>Base!$M6,"↑",IF(Changed!$M6<Base!$M6," ↓",""))} -> 80 | N6: =Changed!G6-Base!G6 -> 0 | P6: I would have liked to use the Johto dex as the baseline but I think that would cause more harm than good
A7: 6 | B7: Charizard | C7: =IF(Changed!C7<>"", Changed!C7, "") -> Fire | D7: =IF(Changed!D7<>"", Changed!D7, "") -> Flying | E7: =IF(Changed!E7<>"", Changed!E7, "") -> Blaze | F7: =IF(Changed!F7<>"", Changed!F7, "") -> Solar Power | G7: {=INDEX(Changed!$G:$G,ROW())&IF(Changed!$G7>Base!$G7,"↑",IF(Changed!$G7<Base!$G7," ↓",""))} -> 534 | H7: {=INDEX(Changed!$H:$H,ROW())&IF(Changed!$H7>Base!$H7,"↑",IF(Changed!$H7<Base!$H7," ↓",""))} -> 78 | I7: {=INDEX(Changed!$I:$I,ROW())&IF(Changed!$I7>Base!$I7,"↑",IF(Changed!$I7<Base!$I7," ↓",""))} -> 84 | J7: {=INDEX(Changed!$J:$J,ROW())&IF(Changed!$J7>Base!$J7,"↑",IF(Changed!$J7<Base!$J7," ↓",""))} -> 78 | K7: {=INDEX(Changed!$K:$K,ROW())&IF(Changed!$K7>Base!$K7,"↑",IF(Changed!$K7<Base!$K7," ↓",""))} -> 109 | L7: {=INDEX(Changed!$L:$L,ROW())&IF(Changed!$L7>Base!$L7,"↑",IF(Changed!$L7<Base!$L7," ↓",""))} -> 85 | M7: {=INDEX(Changed!$M:$M,ROW())&IF(Changed!$M7>Base!$M7,"↑",IF(Changed!$M7<Base!$M7," ↓",""))} -> 100 | N7: =Changed!G7-Base!G7 -> 0
A8: 7 | B8: Squirtle | C8: =IF(Changed!C8<>"", Changed!C8, "") -> Water | D8: =IF(Changed!D8<>"", Changed!D8, "") | E8: =IF(Changed!E8<>"", Changed!E8, "") -> Torrent | F8: =IF(Changed!F8<>"", Changed!F8, "") -> Mega Launcher | G8: {=INDEX(Changed!$G:$G,ROW())&IF(Changed!$G8>Base!$G8,"↑",IF(Changed!$G8<Base!$G8," ↓",""))} -> 314 | H8: {=INDEX(Changed!$H:$H,ROW())&IF(Changed!$H8>Base!$H8,"↑",IF(Changed!$H8<Base!$H8," ↓",""))} -> 44 | I8: {=INDEX(Changed!$I:$I,ROW())&IF(Changed!$I8>Base!$I8,"↑",IF(Changed!$I8<Base!$I8," ↓",""))} -> 48 | J8: {=INDEX(Changed!$J:$J,ROW())&IF(Changed!$J8>Base!$J8,"↑",IF(Changed!$J8<Base!$J8," ↓",""))} -> 65 | K8: {=INDEX(Changed!$K:$K,ROW())&IF(Changed!$K8>Base!$K8,"↑",IF(Changed!$K8<Base!$K8," ↓",""))} -> 50 | L8: {=INDEX(Changed!$L:$L,ROW())&IF(Changed!$L8>Base!$L8,"↑",IF(Changed!$L8<Base!$L8," ↓",""))} -> 64 | M8: {=INDEX(Changed!$M:$M,ROW())&IF(Changed!$M8>Base!$M8,"↑",IF(Changed!$M8<Base!$M8," ↓",""))} -> 43 | N8: =Changed!G8-Base!G8 -> 0 | P8: Any changes are in BOLD and are Underlined.
A9: 8 | B9: Wartortle | C9: =IF(Changed!C9<>"", Changed!C9, "") -> Water | D9: =IF(Changed!D9<>"", Changed!D9, "") | E9: =IF(Changed!E9<>"", Changed!E9, "") -> Torrent | F9: =IF(Changed!F9<>"", Changed!F9, "") -> Mega Launcher | G9: {=INDEX(Changed!$G:$G,ROW())&IF(Changed!$G9>Base!$G9,"↑",IF(Changed!$G9<Base!$G9," ↓",""))} -> 405 | H9: {=INDEX(Changed!$H:$H,ROW())&IF(Changed!$H9>Base!$H9,"↑",IF(Changed!$H9<Base!$H9," ↓",""))} -> 59 | I9: {=INDEX(Changed!$I:$I,ROW())&IF(Changed!$I9>Base!$I9,"↑",IF(Changed!$I9<Base!$I9," ↓",""))} -> 63 | J9: {=INDEX(Changed!$J:$J,ROW())&IF(Changed!$J9>Base!$J9,"↑",IF(Changed!$J9<Base!$J9," ↓",""))} -> 80 | K9: {=INDEX(Changed!$K:$K,ROW())&IF(Changed!$K9>Base!$K9,"↑",IF(Changed!$K9<Base!$K9," ↓",""))} -> 65 | L9: {=INDEX(Changed!$L:$L,ROW())&IF(Changed!$L9>Base!$L9,"↑",IF(Changed!$L9<Base!$L9," ↓",""))} -> 80 | M9: {=INDEX(Changed!$M:$M,ROW())&IF(Changed!$M9>Base!$M9,"↑",IF(Changed!$M9<Base!$M9," ↓",""))} -> 58 | N9: =Changed!G9-Base!G9 -> 0 | P9: Stat Changes are also accompanied by an arrow, going up or down based on the change.
A10: 9 | B10: Blastoise | C10: =IF(Changed!C10<>"", Changed!C10, "") -> Water | D10: =IF(Changed!D10<>"", Changed!D10, "") | E10: =IF(Changed!E10<>"", Changed!E10, "") -> Torrent | F10: =IF(Changed!F10<>"", Changed!F10, "") -> Mega Launcher | G10: {=INDEX(Changed!$G:$G,ROW())&IF(Changed!$G10>Base!$G10,"↑",IF(Changed!$G10<Base!$G10," ↓",""))} -> 530 | H10: {=INDEX(Changed!$H:$H,ROW())&IF(Changed!$H10>Base!$H10,"↑",IF(Changed!$H10<Base!$H10," ↓",""))} -> 79 | I10: {=INDEX(Changed!$I:$I,ROW())&IF(Changed!$I10>Base!$I10,"↑",IF(Changed!$I10<Base!$I10," ↓",""))} -> 83 | J10: {=INDEX(Changed!$J:$J,ROW())&IF(Changed!$J10>Base!$J10,"↑",IF(Changed!$J10<Base!$J10," ↓",""))} -> 100 | K10: {=INDEX(Changed!$K:$K,ROW())&IF(Changed!$K10>Base!$K10,"↑",IF(Changed!$K10<Base!$K10," ↓",""))} -> 85 | L10: {=INDEX(Changed!$L:$L,ROW())&IF(Changed!$L10>Base!$L10,"↑",IF(Changed!$L10<Base!$L10," ↓",""))} -> 105 | M10: {=INDEX(Changed!$M:$M,ROW())&IF(Changed!$M10>Base!$M10,"↑",IF(Changed!$M10<Base!$M10," ↓",""))} -> 78 | N10: =Changed!G10-Base!G10 -> 0
A11: 10 | B11: Caterpie | C11: =IF(Changed!C11<>"", Changed!C11, "") -> Bug | D11: =IF(Changed!D11<>"", Changed!D11, "") | E11: =IF(Changed!E11<>"", Changed!E11, "") -> Shield Dust | F11: =IF(Changed!F11<>"", Changed!F11, "") | G11: {=INDEX(Changed!$G:$G,ROW())&IF(Changed!$G11>Base!$G11,"↑",IF(Changed!$G11<Base!$G11," ↓",""))} -> 195 | H11: {=INDEX(Changed!$H:$H,ROW())&IF(Changed!$H11>Base!$H11,"↑",IF(Changed!$H11<Base!$H11," ↓",""))} -> 45 | I11: {=INDEX(Changed!$I:$I,ROW())&IF(Changed!$I11>Base!$I11,"↑",IF(Changed!$I11<Base!$I11," ↓",""))} -> 30 | J11: {=INDEX(Changed!$J:$J,ROW())&IF(Changed!$J11>Base!$J11,"↑",IF(Changed!$J11<Base!$J11," ↓",""))} -> 35 | K11: {=INDEX(Changed!$K:$K,ROW())&IF(Changed!$K11>Base!$K11,"↑",IF(Changed!$K11<Base!$K11," ↓",""))} -> 20 | L11: {=INDEX(Changed!$L:$L,ROW())&IF(Changed!$L11>Base!$L11,"↑",IF(Changed!$L11<Base!$L11," ↓",""))} -> 20 | M11: {=INDEX(Changed!$M:$M,ROW())&IF(Changed!$M11>Base!$M11,"↑",IF(Changed!$M11<Base!$M11," ↓",""))} -> 45 | N11: =Changed!G11-Base!G11 -> 0
A12: 11 | B12: Metapod | C12: =IF(Changed!C12<>"", Changed!C12, "") -> Bug | D12: =IF(Changed!D12<>"", Changed!D12, "") | E12: =IF(Changed!E12<>"", Changed!E12, "") -> Shed Skin | F12: =IF(Changed!F12<>"", Changed!F12, "") | G12: {=INDEX(Changed!$G:$G,ROW())&IF(Changed!$G12>Base!$G12,"↑",IF(Changed!$G12<Base!$G12," ↓",""))} -> 205 | H12: {=INDEX(Changed!$H:$H,ROW())&IF(Changed!$H12>Base!$H12,"↑",IF(Changed!$H12<Base!$H12," ↓",""))} -> 50 | I12: {=INDEX(Changed!$I:$I,ROW())&IF(Changed!$I12>Base!$I12,"↑",IF(Changed!$I12<Base!$I12," ↓",""))} -> 20 | J12: {=INDEX(Changed!$J:$J,ROW())&IF(Changed!$J12>Base!$J12,"↑",IF(Changed!$J12<Base!$J12," ↓",""))} -> 55 | K12: {=INDEX(Changed!$K:$K,ROW())&IF(Changed!$K12>Base!$K12,"↑",IF(Changed!$K12<Base!$K12," ↓",""))} -> 25 | L12: {=INDEX(Changed!$L:$L,ROW())&IF(Changed!$L12>Base!$L12,"↑",IF(Changed!$L12<Base!$L12," ↓",""))} -> 25 | M12: {=INDEX(Changed!$M:$M,ROW())&IF(Changed!$M12>Base!$M12,"↑",IF(Changed!$M12<Base!$M12," ↓",""))} -> 30 | N12: =Changed!G12-Base!G12 -> 0 | P12: You can only sort by Dex and Name in this.
A13: 12 | B13: Butterfree | C13: =IF(Changed!C13<>"", Changed!C13, "") -> Bug | D13: =IF(Changed!D13<>"", Changed!D13, "") -> Psychic | E13: =IF(Changed!E13<>"", Changed!E13, "") -> Compound Eyes | F13: =IF(Changed!F13<>"", Changed!F13, "") | G13: {=INDEX(Changed!$G:$G,ROW())&IF(Changed!$G13>Base!$G13,"↑",IF(Changed!$G13<Base!$G13," ↓",""))} -> 402↑ | H13: {=INDEX(Changed!$H:$H,ROW())&IF(Changed!$H13>Base!$H13,"↑",IF(Changed!$H13<Base!$H13," ↓",""))} -> 60 | I13: {=INDEX(Changed!$I:$I,ROW())&IF(Changed!$I13>Base!$I13,"↑",IF(Changed!$I13<Base!$I13," ↓",""))} -> 45 | J13: {=INDEX(Changed!$J:$J,ROW())&IF(Changed!$J13>Base!$J13,"↑",IF(Changed!$J13<Base!$J13," ↓",""))} -> 50 | K13: {=INDEX(Changed!$K:$K,ROW())&IF(Changed!$K13>Base!$K13,"↑",IF(Changed!$K13<Base!$K13," ↓",""))} -> 97↑ | L13: {=INDEX(Changed!$L:$L,ROW())&IF(Changed!$L13>Base!$L13,"↑",IF(Changed!$L13<Base!$L13," ↓",""))} -> 80 | M13: {=INDEX(Changed!$M:$M,ROW())&IF(Changed!$M13>Base!$M13,"↑",IF(Changed!$M13<Base!$M13," ↓",""))} -> 70 | N13: =Changed!G13-Base!G13 -> 17 | P13: Use the 'Changed' sheet if you want to sort by column.
A14: 13 | B14: Weedle | C14: =IF(Changed!C14<>"", Changed!C14, "") -> Bug | D14: =IF(Changed!D14<>"", Changed!D14, "") -> Poison | E14: =IF(Changed!E14<>"", Changed!E14, "") -> Shield Dust | F14: =IF(Changed!F14<>"", Changed!F14, "") | G14: {=INDEX(Changed!$G:$G,ROW())&IF(Changed!$G14>Base!$G14,"↑",IF(Changed!$G14<Base!$G14," ↓",""))} -> 195 | H14: {=INDEX(Changed!$H:$H,ROW())&IF(Changed!$H14>Base!$H14,"↑",IF(Changed!$H14<Base!$H14," ↓",""))} -> 40 | I14: {=INDEX(Changed!$I:$I,ROW())&IF(Changed!$I14>Base!$I14,"↑",IF(Changed!$I14<Base!$I14," ↓",""))} -> 35 | J14: {=INDEX(Changed!$J:$J,ROW())&IF(Changed!$J14>Base!$J14,"↑",IF(Changed!$J14<Base!$J14," ↓",""))} -> 30 | K14: {=INDEX(Changed!$K:$K,ROW())&IF(Changed!$K14>Base!$K14,"↑",IF(Changed!$K14<Base!$K14," ↓",""))} -> 20 | L14: {=INDEX(Changed!$L:$L,ROW())&IF(Changed!$L14>Base!$L14,"↑",IF(Changed!$L14<Base!$L14," ↓",""))} -> 20 | M14: {=INDEX(Changed!$M:$M,ROW())&IF(Changed!$M14>Base!$M14,"↑",IF(Changed!$M14<Base!$M14," ↓",""))} -> 50 | N14: =Changed!G14-Base!G14 -> 0 | P14: e.g. find the mon with the highest attack
A15: 14 | B15: Kakuna | C15: =IF(Changed!C15<>"", Changed!C15, "") -> Bug | D15: =IF(Changed!D15<>"", Changed!D15, "") -> Poison | E15: =IF(Changed!E15<>"", Changed!E15, "") -> Shed Skin | F15: =IF(Changed!F15<>"", Changed!F15, "") | G15: {=INDEX(Changed!$G:$G,ROW())&IF(Changed!$G15>Base!$G15,"↑",IF(Changed!$G15<Base!$G15," ↓",""))} -> 205 | H15: {=INDEX(Changed!$H:$H,ROW())&IF(Changed!$H15>Base!$H15,"↑",IF(Changed!$H15<Base!$H15," ↓",""))} -> 45 | I15: {=INDEX(Changed!$I:$I,ROW())&IF(Changed!$I15>Base!$I15,"↑",IF(Changed!$I15<Base!$I15," ↓",""))} -> 25 | J15: {=INDEX(Changed!$J:$J,ROW())&IF(Changed!$J15>Base!$J15,"↑",IF(Changed!$J15<Base!$J15," ↓",""))} -> 50 | K15: {=INDEX(Changed!$K:$K,ROW())&IF(Changed!$K15>Base!$K15,"↑",IF(Changed!$K15<Base!$K15," ↓",""))} -> 25 | L15: {=INDEX(Changed!$L:$L,ROW())&IF(Changed!$L15>Base!$L15,"↑",IF(Changed!$L15<Base!$L15," ↓",""))} -> 25 | M15: {=INDEX(Changed!$M:$M,ROW())&IF(Changed!$M15>Base!$M15,"↑",IF(Changed!$M15<Base!$M15," ↓",""))} -> 35 | N15: =Changed!G15-Base!G15 -> 0
A16: 15 | B16: Beedrill | C16: =IF(Changed!C16<>"", Changed!C16, "") -> Bug | D16: =IF(Changed!D16<>"", Changed!D16, "") -> Poison | E16: =IF(Changed!E16<>"", Changed!E16, "") -> Swarm | F16: =IF(Changed!F16<>"", Changed!F16, "") -> Sharpness | G16: {=INDEX(Changed!$G:$G,ROW())&IF(Changed!$G16>Base!$G16,"↑",IF(Changed!$G16<Base!$G16," ↓",""))} -> 412↑ | H16: {=INDEX(Changed!$H:$H,ROW())&IF(Changed!$H16>Base!$H16,"↑",IF(Changed!$H16<Base!$H16," ↓",""))} -> 65 | I16: {=INDEX(Changed!$I:$I,ROW())&IF(Changed!$I16>Base!$I16,"↑",IF(Changed!$I16<Base!$I16," ↓",""))} -> 92↑ | J16: {=INDEX(Changed!$J:$J,ROW())&IF(Changed!$J16>Base!$J16,"↑",IF(Changed!$J16<Base!$J16," ↓",""))} -> 40 | K16: {=INDEX(Changed!$K:$K,ROW())&IF(Changed!$K16>Base!$K16,"↑",IF(Changed!$K16<Base!$K16," ↓",""))} -> 45 | L16: {=INDEX(Changed!$L:$L,ROW())&IF(Changed!$L16>Base!$L16,"↑",IF(Changed!$L16<Base!$L16," ↓",""))} -> 80 | M16: {=INDEX(Changed!$M:$M,ROW())&IF(Changed!$M16>Base!$M16,"↑",IF(Changed!$M16<Base!$M16," ↓",""))} -> 90↑ | N16: =Changed!G16-Base!G16 -> 27
A17: 16 | B17: Pidgey | C17: =IF(Changed!C17<>"", Changed!C17, "") -> Flying | D17: =IF(Changed!D17<>"", Changed!D17, "") -> None | E17: =IF(Changed!E17<>"", Changed!E17, "") -> Keen Eye | F17: =IF(Changed!F17<>"", Changed!F17, "") -> Tangled Feet | G17: {=INDEX(Changed!$G:$G,ROW())&IF(Changed!$G17>Base!$G17,"↑",IF(Changed!$G17<Base!$G17," ↓",""))} -> 251 | H17: {=INDEX(Changed!$H:$H,ROW())&IF(Changed!$H17>Base!$H17,"↑",IF(Changed!$H17<Base!$H17," ↓",""))} -> 40 | I17: {=INDEX(Changed!$I:$I,ROW())&IF(Changed!$I17>Base!$I17,"↑",IF(Changed!$I17<Base!$I17," ↓",""))} -> 45 | J17: {=INDEX(Changed!$J:$J,ROW())&IF(Changed!$J17>Base!$J17,"↑",IF(Changed!$J17<Base!$J17," ↓",""))} -> 40 | K17: {=INDEX(Changed!$K:$K,ROW())&IF(Changed!$K17>Base!$K17,"↑",IF(Changed!$K17<Base!$K17," ↓",""))} -> 35 | L17: {=INDEX(Changed!$L:$L,ROW())&IF(Changed!$L17>Base!$L17,"↑",IF(Changed!$L17<Base!$L17," ↓",""))} -> 35 | M17: {=INDEX(Changed!$M:$M,ROW())&IF(Changed!$M17>Base!$M17,"↑",IF(Changed!$M17<Base!$M17," ↓",""))} -> 56 | N17: =Changed!G17-Base!G17 -> 0 | P17: If you have a better way of doing this instead of having 3 indentical tables and stuff please lmk
A18: 17 | B18: Pidgeotto | C18: =IF(Changed!C18<>"", Changed!C18, "") -> Flying | D18: =IF(Changed!D18<>"", Changed!D18, "") -> None | E18: =IF(Changed!E18<>"", Changed!E18, "") -> Keen Eye | F18: =IF(Changed!F18<>"", Changed!F18, "") -> Tangled Feet | G18: {=INDEX(Changed!$G:$G,ROW())&IF(Changed!$G18>Base!$G18,"↑",IF(Changed!$G18<Base!$G18," ↓",""))} -> 349 | H18: {=INDEX(Changed!$H:$H,ROW())&IF(Changed!$H18>Base!$H18,"↑",IF(Changed!$H18<Base!$H18," ↓",""))} -> 63 | I18: {=INDEX(Changed!$I:$I,ROW())&IF(Changed!$I18>Base!$I18,"↑",IF(Changed!$I18<Base!$I18," ↓",""))} -> 60 | J18: {=INDEX(Changed!$J:$J,ROW())&IF(Changed!$J18>Base!$J18,"↑",IF(Changed!$J18<Base!$J18," ↓",""))} -> 55 | K18: {=INDEX(Changed!$K:$K,ROW())&IF(Changed!$K18>Base!$K18,"↑",IF(Changed!$K18<Base!$K18," ↓",""))} -> 50 | L18: {=INDEX(Changed!$L:$L,ROW())&IF(Changed!$L18>Base!$L18,"↑",IF(Changed!$L18<Base!$L18," ↓",""))} -> 50 | M18: {=INDEX(Changed!$M:$M,ROW())&IF(Changed!$M18>Base!$M18,"↑",IF(Changed!$M18<Base!$M18," ↓",""))} -> 71 | N18: =Changed!G18-Base!G18 -> 0 | P18: Discord: .rizi.
A19: 18 | B19: Pidgeot | C19: =IF(Changed!C19<>"", Changed!C19, "") -> Flying | D19: =IF(Changed!D19<>"", Changed!D19, "") -> None | E19: =IF(Changed!E19<>"", Changed!E19, "") -> Gale Wings | F19: =IF(Changed!F19<>"", Changed!F19, "") -> Tangled Feet | G19: {=INDEX(Changed!$G:$G,ROW())&IF(Changed!$G19>Base!$G19,"↑",IF(Changed!$G19<Base!$G19," ↓",""))} -> 479↑ | H19: {=INDEX(Changed!$H:$H,ROW())&IF(Changed!$H19>Base!$H19,"↑",IF(Changed!$H19<Base!$H19," ↓",""))} -> 83 | I19: {=INDEX(Changed!$I:$I,ROW())&IF(Changed!$I19>Base!$I19,"↑",IF(Changed!$I19<Base!$I19," ↓",""))} -> 80 | J19: {=INDEX(Changed!$J:$J,ROW())&IF(Changed!$J19>Base!$J19,"↑",IF(Changed!$J19<Base!$J19," ↓",""))} -> 75 | K19: {=INDEX(Changed!$K:$K,ROW())&IF(Changed!$K19>Base!$K19,"↑",IF(Changed!$K19<Base!$K19," ↓",""))} -> 70 | L19: {=INDEX(Changed!$L:$L,ROW())&IF(Changed!$L19>Base!$L19,"↑",IF(Changed!$L19<Base!$L19," ↓",""))} -> 70 | M19: {=INDEX(Changed!$M:$M,ROW())&IF(Changed!$M19>Base!$M19,"↑",IF(Changed!$M19<Base!$M19," ↓",""))} -> 101↑ | N19: =Changed!G19-Base!G19 -> 10
A20: 19 | B20: Rattata | C20: =IF(Changed!C20<>"", Changed!C20, "") -> Normal | D20: =IF(Changed!D20<>"", Changed!D20, "") | E20: =IF(Changed!E20<>"", Changed!E20, "") -> Run Away | F20: =IF(Changed!F20<>"", Changed!F20, "") -> Guts | G20: {=INDEX(Changed!$G:$G,ROW())&IF(Changed!$G20>Base!$G20,"↑",IF(Changed!$G20<Base!$G20," ↓",""))} -> 253 | H20: {=INDEX(Changed!$H:$H,ROW())&IF(Changed!$H20>Base!$H20,"↑",IF(Changed!$H20<Base!$H20," ↓",""))} -> 30 | I20: {=INDEX(Changed!$I:$I,ROW())&IF(Changed!$I20>Base!$I20,"↑",IF(Changed!$I20<Base!$I20," ↓",""))} -> 56 | J20: {=INDEX(Changed!$J:$J,ROW())&IF(Changed!$J20>Base!$J20,"↑",IF(Changed!$J20<Base!$J20," ↓",""))} -> 35 | K20: {=INDEX(Changed!$K:$K,ROW())&IF(Changed!$K20>Base!$K20,"↑",IF(Changed!$K20<Base!$K20," ↓",""))} -> 25 | L20: {=INDEX(Changed!$L:$L,ROW())&IF(Changed!$L20>Base!$L20,"↑",IF(Changed!$L20<Base!$L20," ↓",""))} -> 35 | M20: {=INDEX(Changed!$M:$M,ROW())&IF(Changed!$M20>Base!$M20,"↑",IF(Changed!$M20<Base!$M20," ↓",""))} -> 72 | N20: =Changed!G20-Base!G20 -> 0
A21: 20 | B21: Raticate | C21: =IF(Changed!C21<>"", Changed!C21, "") -> Normal | D21: =IF(Changed!D21<>"", Changed!D21, "") | E21: =IF(Changed!E21<>"", Changed!E21, "") -> Strong Jaw | F21: =IF(Changed!F21<>"", Changed!F21, "") -> Guts | G21: {=INDEX(Changed!$G:$G,ROW())&IF(Changed!$G21>Base!$G21,"↑",IF(Changed!$G21<Base!$G21," ↓",""))} -> 420↑ | H21: {=INDEX(Changed!$H:$H,ROW())&IF(Changed!$H21>Base!$H21,"↑",IF(Changed!$H21<Base!$H21," ↓",""))} -> 55 | I21: {=INDEX(Changed!$I:$I,ROW())&IF(Changed!$I21>Base!$I21,"↑",IF(Changed!$I21<Base!$I21," ↓",""))} -> 81 | J21: {=INDEX(Changed!$J:$J,ROW())&IF(Changed!$J21>Base!$J21,"↑",IF(Changed!$J21<Base!$J21," ↓",""))} -> 60 | K21: {=INDEX(Changed!$K:$K,ROW())&IF(Changed!$K21>Base!$K21,"↑",IF(Changed!$K21<Base!$K21," ↓",""))} -> 50 | L21: {=INDEX(Changed!$L:$L,ROW())&IF(Changed!$L21>Base!$L21,"↑",IF(Changed!$L21<Base!$L21," ↓",""))} -> 70 | M21: {=INDEX(Changed!$M:$M,ROW())&IF(Changed!$M21>Base!$M21,"↑",IF(Changed!$M21<Base!$M21," ↓",""))} -> 104↑ | N21: =Changed!G21-Base!G21 -> 7
A22: 21 | B22: Ekans | C22: =IF(Changed!C22<>"", Changed!C22, "") -> Poison | D22: =IF(Changed!D22<>"", Changed!D22, "") | E22: =IF(Changed!E22<>"", Changed!E22, "") -> Intimidate | F22: =IF(Changed!F22<>"", Changed!F22, "") -> Shed Skin | G22: {=INDEX(Changed!$G:$G,ROW())&IF(Changed!$G22>Base!$G22,"↑",IF(Changed!$G22<Base!$G22," ↓",""))} -> 288 | H22: {=INDEX(Changed!$H:$H,ROW())&IF(Changed!$H22>Base!$H22,"↑",IF(Changed!$H22<Base!$H22," ↓",""))} -> 35 | I22: {=INDEX(Changed!$I:$I,ROW())&IF(Changed!$I22>Base!$I22,"↑",IF(Changed!$I22<Base!$I22," ↓",""))} -> 60 | J22: {=INDEX(Changed!$J:$J,ROW())&IF(Changed!$J22>Base!$J22,"↑",IF(Changed!$J22<Base!$J22," ↓",""))} -> 44 | K22: {=INDEX(Changed!$K:$K,ROW())&IF(Changed!$K22>Base!$K22,"↑",IF(Changed!$K22<Base!$K22," ↓",""))} -> 40 | L22: {=INDEX(Changed!$L:$L,ROW())&IF(Changed!$L22>Base!$L22,"↑",IF(Changed!$L22<Base!$L22," ↓",""))} -> 54 | M22: {=INDEX(Changed!$M:$M,ROW())&IF(Changed!$M22>Base!$M22,"↑",IF(Changed!$M22<Base!$M22," ↓",""))} -> 55 | N22: =Changed!G22-Base!G22 -> 0
A23: 22 | B23: Arbok | C23: =IF(Changed!C23<>"", Changed!C23, "") -> Poison | D23: =IF(Changed!D23<>"", Changed!D23, "") -> Dragon | E23: =IF(Changed!E23<>"", Changed!E23, "") -> Intimidate | F23: =IF(Changed!F23<>"", Changed!F23, "") -> Shed Skin | G23: {=INDEX(Changed!$G:$G,ROW())&IF(Changed!$G23>Base!$G23,"↑",IF(Changed!$G23<Base!$G23," ↓",""))} -> 448 | H23: {=INDEX(Changed!$H:$H,ROW())&IF(Changed!$H23>Base!$H23,"↑",IF(Changed!$H23<Base!$H23," ↓",""))} -> 60 | I23: {=INDEX(Changed!$I:$I,ROW())&IF(Changed!$I23>Base!$I23,"↑",IF(Changed!$I23<Base!$I23," ↓",""))} -> 95 | J23: {=INDEX(Changed!$J:$J,ROW())&IF(Changed!$J23>Base!$J23,"↑",IF(Changed!$J23<Base!$J23," ↓",""))} -> 69 | K23: {=INDEX(Changed!$K:$K,ROW())&IF(Changed!$K23>Base!$K23,"↑",IF(Changed!$K23<Base!$K23," ↓",""))} -> 65 | L23: {=INDEX(Changed!$L:$L,ROW())&IF(Changed!$L23>Base!$L23,"↑",IF(Changed!$L23<Base!$L23," ↓",""))} -> 79 | M23: {=INDEX(Changed!$M:$M,ROW())&IF(Changed!$M23>Base!$M23,"↑",IF(Changed!$M23<Base!$M23," ↓",""))} -> 80 | N23: =Changed!G23-Base!G23 -> 0
A24: 23 | B24: Pichu | C24: =IF(Changed!C24<>"", Changed!C24, "") -> Electric | D24: =IF(Changed!D24<>"", Changed!D24, "") | E24: =IF(Changed!E24<>"", Changed!E24, "") -> Static | F24: =IF(Changed!F24<>"", Changed!F24, "") -> Transistor | G24: {=INDEX(Changed!$G:$G,ROW())&IF(Changed!$G24>Base!$G24,"↑",IF(Changed!$G24<Base!$G24," ↓",""))} -> 205 | H24: {=INDEX(Changed!$H:$H,ROW())&IF(Changed!$H24>Base!$H24,"↑",IF(Changed!$H24<Base!$H24," ↓",""))} -> 20 | I24: {=INDEX(Changed!$I:$I,ROW())&IF(Changed!$I24>Base!$I24,"↑",IF(Changed!$I24<Base!$I24," ↓",""))} -> 40 | J24: {=INDEX(Changed!$J:$J,ROW())&IF(Changed!$J24>Base!$J24,"↑",IF(Changed!$J24<Base!$J24," ↓",""))} -> 15 | K24: {=INDEX(Changed!$K:$K,ROW())&IF(Changed!$K24>Base!$K24,"↑",IF(Changed!$K24<Base!$K24," ↓",""))} -> 35 | L24: {=INDEX(Changed!$L:$L,ROW())&IF(Changed!$L24>Base!$L24,"↑",IF(Changed!$L24<Base!$L24," ↓",""))} -> 35 | M24: {=INDEX(Changed!$M:$M,ROW())&IF(Changed!$M24>Base!$M24,"↑",IF(Changed!$M24<Base!$M24," ↓",""))} -> 60 | N24: =Changed!G24-Base!G24 -> 0
A25: 24 | B25: Pikachu | C25: =IF(Changed!C25<>"", Changed!C25, "") -> Electric | D25: =IF(Changed!D25<>"", Changed!D25, "") | E25: =IF(Changed!E25<>"", Changed!E25, "") -> Static | F25: =IF(Changed!F25<>"", Changed!F25, "") -> Transistor | G25: {=INDEX(Changed!$G:$G,ROW())&IF(Changed!$G25>Base!$G25,"↑",IF(Changed!$G25<Base!$G25," ↓",""))} -> 300 | H25: {=INDEX(Changed!$H:$H,ROW())&IF(Changed!$H25>Base!$H25,"↑",IF(Changed!$H25<Base!$H25," ↓",""))} -> 35 | I25: {=INDEX(Changed!$I:$I,ROW())&IF(Changed!$I25>Base!$I25,"↑",IF(Changed!$I25<Base!$I25," ↓",""))} -> 55 | J25: {=INDEX(Changed!$J:$J,ROW())&IF(Changed!$J25>Base!$J25,"↑",IF(Changed!$J25<Base!$J25," ↓",""))} -> 30 | K25: {=INDEX(Changed!$K:$K,ROW())&IF(Changed!$K25>Base!$K25,"↑",IF(Changed!$K25<Base!$K25," ↓",""))} -> 50 | L25: {=INDEX(Changed!$L:$L,ROW())&IF(Changed!$L25>Base!$L25,"↑",IF(Changed!$L25<Base!$L25," ↓",""))} -> 40 | M25: {=INDEX(Changed!$M:$M,ROW())&IF(Changed!$M25>Base!$M25,"↑",IF(Changed!$M25<Base!$M25," ↓",""))} -> 90 | N25: =Changed!G25-Base!G25 -> 0
A26: 25 | B26: Raichu | C26: =IF(Changed!C26<>"", Changed!C26, "") -> Electric | D26: =IF(Changed!D26<>"", Changed!D26, "") | E26: =IF(Changed!E26<>"", Changed!E26, "") -> Static | F26: =IF(Changed!F26<>"", Changed!F26, "") -> Transistor | G26: {=INDEX(Changed!$G:$G,ROW())&IF(Changed!$G26>Base!$G26,"↑",IF(Changed!$G26<Base!$G26," ↓",""))} -> 475 | H26: {=INDEX(Changed!$H:$H,ROW())&IF(Changed!$H26>Base!$H26,"↑",IF(Changed!$H26<Base!$H26," ↓",""))} -> 60 | I26: {=INDEX(Changed!$I:$I,ROW())&IF(Changed!$I26>Base!$I26,"↑",IF(Changed!$I26<Base!$I26," ↓",""))} -> 70 ↓ | J26: {=INDEX(Changed!$J:$J,ROW())&IF(Changed!$J26>Base!$J26,"↑",IF(Changed!$J26<Base!$J26," ↓",""))} -> 65↑ | K26: {=INDEX(Changed!$K:$K,ROW())&IF(Changed!$K26>Base!$K26,"↑",IF(Changed!$K26<Base!$K26," ↓",""))} -> 95↑ | L26: {=INDEX(Changed!$L:$L,ROW())&IF(Changed!$L26>Base!$L26,"↑",IF(Changed!$L26<Base!$L26," ↓",""))} -> 85↑ | M26: {=INDEX(Changed!$M:$M,ROW())&IF(Changed!$M26>Base!$M26,"↑",IF(Changed!$M26<Base!$M26," ↓",""))} -> 100 | N26: =Changed!G26-Base!G26 -> 0
A27: 26 | B27: Sandshrew | C27: =IF(Changed!C27<>"", Changed!C27, "") -> Ground | D27: =IF(Changed!D27<>"", Changed!D27, "") | E27: =IF(Changed!E27<>"", Changed!E27, "") -> Sand Rush | F27: =IF(Changed!F27<>"", Changed!F27, "") -> Sharpness | G27: {=INDEX(Changed!$G:$G,ROW())&IF(Changed!$G27>Base!$G27,"↑",IF(Changed!$G27<Base!$G27," ↓",""))} -> 300 | H27: {=INDEX(Changed!$H:$H,ROW())&IF(Changed!$H27>Base!$H27,"↑",IF(Changed!$H27<Base!$H27," ↓",""))} -> 50 | I27: {=INDEX(Changed!$I:$I,ROW())&IF(Changed!$I27>Base!$I27,"↑",IF(Changed!$I27<Base!$I27," ↓",""))} -> 75 | J27: {=INDEX(Changed!$J:$J,ROW())&IF(Changed!$J27>Base!$J27,"↑",IF(Changed!$J27<Base!$J27," ↓",""))} -> 85 | K27: {=INDEX(Changed!$K:$K,ROW())&IF(Changed!$K27>Base!$K27,"↑",IF(Changed!$K27<Base!$K27," ↓",""))} -> 20 | L27: {=INDEX(Changed!$L:$L,ROW())&IF(Changed!$L27>Base!$L27,"↑",IF(Changed!$L27<Base!$L27," ↓",""))} -> 30 | M27: {=INDEX(Changed!$M:$M,ROW())&IF(Changed!$M27>Base!$M27,"↑",IF(Changed!$M27<Base!$M27," ↓",""))} -> 40 | N27: =Changed!G27-Base!G27 -> 0
A28: 27 | B28: Sandslash | C28: =IF(Changed!C28<>"", Changed!C28, "") -> Ground | D28: =IF(Changed!D28<>"", Changed!D28, "") | E28: =IF(Changed!E28<>"", Changed!E28, "") -> Sand Rush | F28: =IF(Changed!F28<>"", Changed!F28, "") -> Sharpness | G28: {=INDEX(Changed!$G:$G,ROW())&IF(Changed!$G28>Base!$G28,"↑",IF(Changed!$G28<Base!$G28," ↓",""))} -> 450 | H28: {=INDEX(Changed!$H:$H,ROW())&IF(Changed!$H28>Base!$H28,"↑",IF(Changed!$H28<Base!$H28," ↓",""))} -> 75 | I28: {=INDEX(Changed!$I:$I,ROW())&IF(Changed!$I28>Base!$I28,"↑",IF(Changed!$I28<Base!$I28," ↓",""))} -> 100 | J28: {=INDEX(Changed!$J:$J,ROW())&IF(Changed!$J28>Base!$J28,"↑",IF(Changed!$J28<Base!$J28," ↓",""))} -> 110 | K28: {=INDEX(Changed!$K:$K,ROW())&IF(Changed!$K28>Base!$K28,"↑",IF(Changed!$K28<Base!$K28," ↓",""))} -> 45 | L28: {=INDEX(Changed!$L:$L,ROW())&IF(Changed!$L28>Base!$L28,"↑",IF(Changed!$L28<Base!$L28," ↓",""))} -> 55 | M28: {=INDEX(Changed!$M:$M,ROW())&IF(Changed!$M28>Base!$M28,"↑",IF(Changed!$M28<Base!$M28," ↓",""))} -> 65 | N28: =Changed!G28-Base!G28 -> 0
A29: 28 | B29: Nidoran♀ | C29: =IF(Changed!C29<>"", Changed!C29, "") -> Poison | D29: =IF(Changed!D29<>"", Changed!D29, "") | E29: =IF(Changed!E29<>"", Changed!E29, "") -> Poison Point | F29: =IF(Changed!F29<>"", Changed!F29, "") -> Rivalry | G29: {=INDEX(Changed!$G:$G,ROW())&IF(Changed!$G29>Base!$G29,"↑",IF(Changed!$G29<Base!$G29," ↓",""))} -> 275 | H29: {=INDEX(Changed!$H:$H,ROW())&IF(Changed!$H29>Base!$H29,"↑",IF(Changed!$H29<Base!$H29," ↓",""))} -> 55 | I29: {=INDEX(Changed!$I:$I,ROW())&IF(Changed!$I29>Base!$I29,"↑",IF(Changed!$I29<Base!$I29," ↓",""))} -> 47 | J29: {=INDEX(Changed!$J:$J,ROW())&IF(Changed!$J29>Base!$J29,"↑",IF(Changed!$J29<Base!$J29," ↓",""))} -> 52 | K29: {=INDEX(Changed!$K:$K,ROW())&IF(Changed!$K29>Base!$K29,"↑",IF(Changed!$K29<Base!$K29," ↓",""))} -> 40 | L29: {=INDEX(Changed!$L:$L,ROW())&IF(Changed!$L29>Base!$L29,"↑",IF(Changed!$L29<Base!$L29," ↓",""))} -> 40 | M29: {=INDEX(Changed!$M:$M,ROW())&IF(Changed!$M29>Base!$M29,"↑",IF(Changed!$M29<Base!$M29," ↓",""))} -> 41 | N29: =Changed!G29-Base!G29 -> 0
A30: 29 | B30: Nidorina | C30: =IF(Changed!C30<>"", Changed!C30, "") -> Poison | D30: =IF(Changed!D30<>"", Changed!D30, "") | E30: =IF(Changed!E30<>"", Changed!E30, "") -> Poison Point | F30: =IF(Changed!F30<>"", Changed!F30, "") -> Rivalry | G30: {=INDEX(Changed!$G:$G,ROW())&IF(Changed!$G30>Base!$G30,"↑",IF(Changed!$G30<Base!$G30," ↓",""))} -> 365 | H30: {=INDEX(Changed!$H:$H,ROW())&IF(Changed!$H30>Base!$H30,"↑",IF(Changed!$H30<Base!$H30," ↓",""))} -> 70 | I30: {=INDEX(Changed!$I:$I,ROW())&IF(Changed!$I30>Base!$I30,"↑",IF(Changed!$I30<Base!$I30," ↓",""))} -> 62 | J30: {=INDEX(Changed!$J:$J,ROW())&IF(Changed!$J30>Base!$J30,"↑",IF(Changed!$J30<Base!$J30," ↓",""))} -> 67 | K30: {=INDEX(Changed!$K:$K,ROW())&IF(Changed!$K30>Base!$K30,"↑",IF(Changed!$K30<Base!$K30," ↓",""))} -> 55 | L30: {=INDEX(Changed!$L:$L,ROW())&IF(Changed!$L30>Base!$L30,"↑",IF(Changed!$L30<Base!$L30," ↓",""))} -> 55 | M30: {=INDEX(Changed!$M:$M,ROW())&IF(Changed!$M30>Base!$M30,"↑",IF(Changed!$M30<Base!$M30," ↓",""))} -> 56 | N30: =Changed!G30-Base!G30 -> 0
... A86: 85 | B86: Slowbro | C86: =IF(Changed!C86<>"", Changed!C86, "") -> Water | D86: =IF(Changed!D86<>"", Changed!D86, "") -> Psychic | E86: =IF(Changed!E86<>"", Changed!E86, "") -> Oblivious | F86: =IF(Changed!F86<>"", Changed!F86, "") -> Regenerator | G86: {=INDEX(Changed!$G:$G,ROW())&IF(Changed!$G86>Base!$G86,"↑",IF(Changed!$G86<Base!$G86," ↓",""))} -> 490 | H86: {=INDEX(Changed!$H:$H,ROW())&IF(Changed!$H86>Base!$H86,"↑",IF(Changed!$H86<Base!$H86," ↓",""))} -> 95 | I86: {=INDEX(Changed!$I:$I,ROW())&IF(Changed!$I86>Base!$I86,"↑",IF(Changed!$I86<Base!$I86," ↓",""))} -> 75 | J86: {=INDEX(Changed!$J:$J,ROW())&IF(Changed!$J86>Base!$J86,"↑",IF(Changed!$J86<Base!$J86," ↓",""))} -> 110 | K86: {=INDEX(Changed!$K:$K,ROW())&IF(Changed!$K86>Base!$K86,"↑",IF(Changed!$K86<Base!$K86," ↓",""))} -> 100 | L86: {=INDEX(Changed!$L:$L,ROW())&IF(Changed!$L86>Base!$L86,"↑",IF(Changed!$L86<Base!$L86," ↓",""))} -> 80 | M86: {=INDEX(Changed!$M:$M,ROW())&IF(Changed!$M86>Base!$M86,"↑",IF(Changed!$M86<Base!$M86," ↓",""))} -> 30 | N86: =Changed!G86-Base!G86 -> 0
A87: 86 | B87: Slowking | C87: =IF(Changed!C87<>"", Changed!C87, "") -> Water | D87: =IF(Changed!D87<>"", Changed!D87, "") -> Psychic | E87: =IF(Changed!F87<>"", Changed!F87, "") -> Own Tempo | F87: =IF(Changed!F87<>"", Changed!F87, "") -> Own Tempo | G87: {=INDEX(Changed!$G:$G,ROW())&IF(Changed!$G87>Base!$G87,"↑",IF(Changed!$G87<Base!$G87," ↓",""))} -> 490 | H87: {=INDEX(Changed!$H:$H,ROW())&IF(Changed!$H87>Base!$H87,"↑",IF(Changed!$H87<Base!$H87," ↓",""))} -> 95 | I87: {=INDEX(Changed!$I:$I,ROW())&IF(Changed!$I87>Base!$I87,"↑",IF(Changed!$I87<Base!$I87," ↓",""))} -> 75 | J87: {=INDEX(Changed!$J:$J,ROW())&IF(Changed!$J87>Base!$J87,"↑",IF(Changed!$J87<Base!$J87," ↓",""))} -> 80 | K87: {=INDEX(Changed!$K:$K,ROW())&IF(Changed!$K87>Base!$K87,"↑",IF(Changed!$K87<Base!$K87," ↓",""))} -> 100 | L87: {=INDEX(Changed!$L:$L,ROW())&IF(Changed!$L87>Base!$L87,"↑",IF(Changed!$L87<Base!$L87," ↓",""))} -> 110 | M87: {=INDEX(Changed!$M:$M,ROW())&IF(Changed!$M87>Base!$M87,"↑",IF(Changed!$M87<Base!$M87," ↓",""))} -> 30 | N87: =Changed!G87-Base!G87 -> 0
A88: 87 | B88: Magnemite | C88: =IF(Changed!C88<>"", Changed!C88, "") -> Electric | D88: =IF(Changed!D88<>"", Changed!D88, "") -> Steel | E88: =IF(Changed!E88<>"", Changed!E88, "") -> Manget Pull | F88: =IF(Changed!F88<>"", Changed!F88, "") -> Levitate | G88: {=INDEX(Changed!$G:$G,ROW())&IF(Changed!$G88>Base!$G88,"↑",IF(Changed!$G88<Base!$G88," ↓",""))} -> 325 | H88: {=INDEX(Changed!$H:$H,ROW())&IF(Changed!$H88>Base!$H88,"↑",IF(Changed!$H88<Base!$H88," ↓",""))} -> 25 | I88: {=INDEX(Changed!$I:$I,ROW())&IF(Changed!$I88>Base!$I88,"↑",IF(Changed!$I88<Base!$I88," ↓",""))} -> 35 | J88: {=INDEX(Changed!$J:$J,ROW())&IF(Changed!$J88>Base!$J88,"↑",IF(Changed!$J88<Base!$J88," ↓",""))} -> 70 | K88: {=INDEX(Changed!$K:$K,ROW())&IF(Changed!$K88>Base!$K88,"↑",IF(Changed!$K88<Base!$K88," ↓",""))} -> 95 | L88: {=INDEX(Changed!$L:$L,ROW())&IF(Changed!$L88>Base!$L88,"↑",IF(Changed!$L88<Base!$L88," ↓",""))} -> 55 | M88: {=INDEX(Changed!$M:$M,ROW())&IF(Changed!$M88>Base!$M88,"↑",IF(Changed!$M88<Base!$M88," ↓",""))} -> 45 | N88: =Changed!G88-Base!G88 -> 0
A89: 88 | B89: Magneton | C89: =IF(Changed!C89<>"", Changed!C89, "") -> Electric | D89: =IF(Changed!D89<>"", Changed!D89, "") -> Steel | E89: =IF(Changed!E89<>"", Changed!E89, "") -> Manget Pull | F89: =IF(Changed!F89<>"", Changed!F89, "") -> Levitate | G89: {=INDEX(Changed!$G:$G,ROW())&IF(Changed!$G89>Base!$G89,"↑",IF(Changed!$G89<Base!$G89," ↓",""))} -> 465 | H89: {=INDEX(Changed!$H:$H,ROW())&IF(Changed!$H89>Base!$H89,"↑",IF(Changed!$H89<Base!$H89," ↓",""))} -> 50 | I89: {=INDEX(Changed!$I:$I,ROW())&IF(Changed!$I89>Base!$I89,"↑",IF(Changed!$I89<Base!$I89," ↓",""))} -> 60 | J89: {=INDEX(Changed!$J:$J,ROW())&IF(Changed!$J89>Base!$J89,"↑",IF(Changed!$J89<Base!$J89," ↓",""))} -> 95 | K89: {=INDEX(Changed!$K:$K,ROW())&IF(Changed!$K89>Base!$K89,"↑",IF(Changed!$K89<Base!$K89," ↓",""))} -> 120 | L89: {=INDEX(Changed!$L:$L,ROW())&IF(Changed!$L89>Base!$L89,"↑",IF(Changed!$L89<Base!$L89," ↓",""))} -> 70 | M89: {=INDEX(Changed!$M:$M,ROW())&IF(Changed!$M89>Base!$M89,"↑",IF(Changed!$M89<Base!$M89," ↓",""))} -> 70 | N89: =Changed!G89-Base!G89 -> 0
A90: 89 | B90: Magnezone | C90: =IF(Changed!C90<>"", Changed!C90, "") -> Electric | D90: =IF(Changed!D90<>"", Changed!D90, "") -> Steel | E90: =IF(Changed!E90<>"", Changed!E90, "") -> Magnet Pull | F90: =IF(Changed!F90<>"", Changed!F90, "") -> Levitate | G90: {=INDEX(Changed!$G:$G,ROW())&IF(Changed!$G90>Base!$G90,"↑",IF(Changed!$G90<Base!$G90," ↓",""))} -> 535 | H90: {=INDEX(Changed!$H:$H,ROW())&IF(Changed!$H90>Base!$H90,"↑",IF(Changed!$H90<Base!$H90," ↓",""))} -> 70 | I90: {=INDEX(Changed!$I:$I,ROW())&IF(Changed!$I90>Base!$I90,"↑",IF(Changed!$I90<Base!$I90," ↓",""))} -> 70 | J90: {=INDEX(Changed!$J:$J,ROW())&IF(Changed!$J90>Base!$J90,"↑",IF(Changed!$J90<Base!$J90," ↓",""))} -> 115 | K90: {=INDEX(Changed!$K:$K,ROW())&IF(Changed!$K90>Base!$K90,"↑",IF(Changed!$K90<Base!$K90," ↓",""))} -> 130 | L90: {=INDEX(Changed!$L:$L,ROW())&IF(Changed!$L90>Base!$L90,"↑",IF(Changed!$L90<Base!$L90," ↓",""))} -> 90 | M90: {=INDEX(Changed!$M:$M,ROW())&IF(Changed!$M90>Base!$M90,"↑",IF(Changed!$M90<Base!$M90," ↓",""))} -> 60 | N90: =Changed!G90-Base!G90 -> 0
A91: 90 | B91: Farfetch'd | C91: =IF(Changed!C91<>"", Changed!C91, "") -> Fighting | D91: =IF(Changed!D91<>"", Changed!D91, "") -> Flying | E91: =IF(Changed!E91<>"", Changed!E91, "") -> Super Luck | F91: =IF(Changed!F91<>"", Changed!F91, "") -> Sniper | G91: {=INDEX(Changed!$G:$G,ROW())&IF(Changed!$G91>Base!$G91,"↑",IF(Changed!$G91<Base!$G91," ↓",""))} -> 377 | H91: {=INDEX(Changed!$H:$H,ROW())&IF(Changed!$H91>Base!$H91,"↑",IF(Changed!$H91<Base!$H91," ↓",""))} -> 52 | I91: {=INDEX(Changed!$I:$I,ROW())&IF(Changed!$I91>Base!$I91,"↑",IF(Changed!$I91<Base!$I91," ↓",""))} -> 90 | J91: {=INDEX(Changed!$J:$J,ROW())&IF(Changed!$J91>Base!$J91,"↑",IF(Changed!$J91<Base!$J91," ↓",""))} -> 55 | K91: {=INDEX(Changed!$K:$K,ROW())&IF(Changed!$K91>Base!$K91,"↑",IF(Changed!$K91<Base!$K91," ↓",""))} -> 58 | L91: {=INDEX(Changed!$L:$L,ROW())&IF(Changed!$L91>Base!$L91,"↑",IF(Changed!$L91<Base!$L91," ↓",""))} -> 62 | M91: {=INDEX(Changed!$M:$M,ROW())&IF(Changed!$M91>Base!$M91,"↑",IF(Changed!$M91<Base!$M91," ↓",""))} -> 60 | N91: =Changed!G91-Base!G91 -> 0
A92: 91 | B92: Sirfetch'd | C92: =IF(Changed!C92<>"", Changed!C92, "") -> Fighting | D92: =IF(Changed!D92<>"", Changed!D92, "") -> Flying | E92: =IF(Changed!E92<>"", Changed!E92, "") -> Super Luck | F92: =IF(Changed!F92<>"", Changed!F92, "") -> Sniper | G92: {=INDEX(Changed!$G:$G,ROW())&IF(Changed!$G92>Base!$G92,"↑",IF(Changed!$G92<Base!$G92," ↓",""))} -> 507 | H92: {=INDEX(Changed!$H:$H,ROW())&IF(Changed!$H92>Base!$H92,"↑",IF(Changed!$H92<Base!$H92," ↓",""))} -> 62 | I92: {=INDEX(Changed!$I:$I,ROW())&IF(Changed!$I92>Base!$I92,"↑",IF(Changed!$I92<Base!$I92," ↓",""))} -> 135 | J92: {=INDEX(Changed!$J:$J,ROW())&IF(Changed!$J92>Base!$J92,"↑",IF(Changed!$J92<Base!$J92," ↓",""))} -> 95 | K92: {=INDEX(Changed!$K:$K,ROW())&IF(Changed!$K92>Base!$K92,"↑",IF(Changed!$K92<Base!$K92," ↓",""))} -> 68 | L92: {=INDEX(Changed!$L:$L,ROW())&IF(Changed!$L92>Base!$L92,"↑",IF(Changed!$L92<Base!$L92," ↓",""))} -> 82 | M92: {=INDEX(Changed!$M:$M,ROW())&IF(Changed!$M92>Base!$M92,"↑",IF(Changed!$M92<Base!$M92," ↓",""))} -> 65 | N92: =Changed!G92-Base!G92 -> 0
A93: 92 | B93: Doduo | C93: =IF(Changed!C93<>"", Changed!C93, "") -> Ground | D93: =IF(Changed!D93<>"", Changed!D93, "") -> Flying | E93: =IF(Changed!E93<>"", Changed!E93, "") -> Parental Bond | F93: =IF(Changed!F93<>"", Changed!F93, "") -> Early Bird | G93: {=INDEX(Changed!$G:$G,ROW())&IF(Changed!$G93>Base!$G93,"↑",IF(Changed!$G93<Base!$G93," ↓",""))} -> 310 | H93: {=INDEX(Changed!$H:$H,ROW())&IF(Changed!$H93>Base!$H93,"↑",IF(Changed!$H93<Base!$H93," ↓",""))} -> 35 | I93: {=INDEX(Changed!$I:$I,ROW())&IF(Changed!$I93>Base!$I93,"↑",IF(Changed!$I93<Base!$I93," ↓",""))} -> 85 | J93: {=INDEX(Changed!$J:$J,ROW())&IF(Changed!$J93>Base!$J93,"↑",IF(Changed!$J93<Base!$J93," ↓",""))} -> 45 | K93: {=INDEX(Changed!$K:$K,ROW())&IF(Changed!$K93>Base!$K93,"↑",IF(Changed!$K93<Base!$K93," ↓",""))} -> 35 | L93: {=INDEX(Changed!$L:$L,ROW())&IF(Changed!$L93>Base!$L93,"↑",IF(Changed!$L93<Base!$L93," ↓",""))} -> 35 | M93: {=INDEX(Changed!$M:$M,ROW())&IF(Changed!$M93>Base!$M93,"↑",IF(Changed!$M93<Base!$M93," ↓",""))} -> 75 | N93: =Changed!G93-Base!G93 -> 0
A94: 93 | B94: Dodrio | C94: =IF(Changed!C94<>"", Changed!C94, "") -> Ground | D94: =IF(Changed!D94<>"", Changed!D94, "") -> Flying | E94: =IF(Changed!E94<>"", Changed!E94, "") -> Parental Bond | F94: =IF(Changed!F94<>"", Changed!F94, "") -> Early Bird | G94: {=INDEX(Changed!$G:$G,ROW())&IF(Changed!$G94>Base!$G94,"↑",IF(Changed!$G94<Base!$G94," ↓",""))} -> 470 | H94: {=INDEX(Changed!$H:$H,ROW())&IF(Changed!$H94>Base!$H94,"↑",IF(Changed!$H94<Base!$H94," ↓",""))} -> 60 | I94: {=INDEX(Changed!$I:$I,ROW())&IF(Changed!$I94>Base!$I94,"↑",IF(Changed!$I94<Base!$I94," ↓",""))} -> 110 | J94: {=INDEX(Changed!$J:$J,ROW())&IF(Changed!$J94>Base!$J94,"↑",IF(Changed!$J94<Base!$J94," ↓",""))} -> 70 | K94: {=INDEX(Changed!$K:$K,ROW())&IF(Changed!$K94>Base!$K94,"↑",IF(Changed!$K94<Base!$K94," ↓",""))} -> 60 | L94: {=INDEX(Changed!$L:$L,ROW())&IF(Changed!$L94>Base!$L94,"↑",IF(Changed!$L94<Base!$L94," ↓",""))} -> 60 | M94: {=INDEX(Changed!$M:$M,ROW())&IF(Changed!$M94>Base!$M94,"↑",IF(Changed!$M94<Base!$M94," ↓",""))} -> 110 | N94: =Changed!G94-Base!G94 -> 0
A95: 94 | B95: Seel | C95: =IF(Changed!C95<>"", Changed!C95, "") -> Water | D95: =IF(Changed!D95<>"", Changed!D95, "") | E95: =IF(Changed!E95<>"", Changed!E95, "") -> Thick Fat | F95: =IF(Changed!F95<>"", Changed!F95, "") -> Refrigerate | G95: {=INDEX(Changed!$G:$G,ROW())&IF(Changed!$G95>Base!$G95,"↑",IF(Changed!$G95<Base!$G95," ↓",""))} -> 335↑ | H95: {=INDEX(Changed!$H:$H,ROW())&IF(Changed!$H95>Base!$H95,"↑",IF(Changed!$H95<Base!$H95," ↓",""))} -> 65 | I95: {=INDEX(Changed!$I:$I,ROW())&IF(Changed!$I95>Base!$I95,"↑",IF(Changed!$I95<Base!$I95," ↓",""))} -> 45 | J95: {=INDEX(Changed!$J:$J,ROW())&IF(Changed!$J95>Base!$J95,"↑",IF(Changed!$J95<Base!$J95," ↓",""))} -> 55 | K95: {=INDEX(Changed!$K:$K,ROW())&IF(Changed!$K95>Base!$K95,"↑",IF(Changed!$K95<Base!$K95," ↓",""))} -> 45 | L95: {=INDEX(Changed!$L:$L,ROW())&IF(Changed!$L95>Base!$L95,"↑",IF(Changed!$L95<Base!$L95," ↓",""))} -> 80↑ | M95: {=INDEX(Changed!$M:$M,ROW())&IF(Changed!$M95>Base!$M95,"↑",IF(Changed!$M95<Base!$M95," ↓",""))} -> 45 | N95: =Changed!G95-Base!G95 -> 10
...

Sheet Evolution
A1: Dex Number | B1: Name | C1: Stage 1 | D1: Method | E1: Stage 2 | F1: Method | G1: Stage 3
A2: 1 | B2: Bulbasaur | C2: =#REF! -> #REF! | D2: Level | E2: =#REF! -> #REF! | F2: Level | G2: =#REF! -> #REF!
A3: 2 | B3: Ivysaur | D3: 20 | F3: 38
A4: 3 | B4: Venusaur | D4: =IP!B2 -> #VALUE! | F4: =IP!B2 -> #VALUE!
A5: 4 | B5: Charmander | C5: =#REF! -> #REF! | D5: Level | E5: =#REF! -> #REF! | F5: Level | G5: =#REF! -> #REF!
A6: 5 | B6: Charmeleon | D6: 20 | F6: 42
A7: 6 | B7: Charizard | D7: =IP!B2 -> #VALUE! | F7: =IP!B2 -> #VALUE!
A8: 7 | B8: Squirtle | C8: =#REF! -> #REF! | D8: Level | E8: =#REF! -> #REF! | F8: Level | G8: =#REF! -> #REF!
A9: 8 | B9: Wartortle | D9: 20 | F9: 42
A10: 9 | B10: Blastoise | D10: =IP!B2 -> #VALUE! | F10: =IP!B2 -> #VALUE!
A11: 10 | B11: Caterpie | C11: =#REF! -> #REF! | D11: Level | E11: =#REF! -> #REF! | F11: Level | G11: =#REF! -> #REF!
A12: 11 | B12: Metapod | D12: 9 | F12: 18
A13: 12 | B13: Butterfree | D13: =IP!B2 -> #VALUE! | F13: =IP!B2 -> #VALUE!
A14: 13 | B14: Weedle | C14: =#REF! -> #REF! | D14: Level | E14: =#REF! -> #REF! | F14: Level | G14: =#REF! -> #REF!
A15: 14 | B15: Kakuna | D15: 9 | F15: 18
A16: 15 | B16: Beedrill | D16: =IP!B2 -> #VALUE! | F16: =IP!B2 -> #VALUE!
A17: 16 | B17: Pidgey | C17: =#REF! -> #REF! | D17: Level | E17: =#REF! -> #REF! | F17: Level | G17: =#REF! -> #REF!
A18: 17 | B18: Pidgeotto | D18: 18 | F18: 38
A19: 18 | B19: Pidgeot | D19: =IP!B2 -> #VALUE! | F19: =IP!B2 -> #VALUE!
A20: 19 | B20: Rattata | C20: =#REF! -> #REF! | D20: Level | E20: =#REF! -> #REF!
A21: 20 | B21: Raticate | D21: 25
D22: =IP!B2 -> #VALUE!
A23: 21 | B23: Ekans | C23: =#REF! -> #REF! | D23: Level | E23: =#REF! -> #REF!
A24: 22 | B24: Arbok | D24: 30
D25: =IP!B2 -> #VALUE!
A26: 23 | B26: Pichu | C26: =#REF! -> #REF! | D26: Level | E26: =#REF! -> #REF! | F26: Level | G26: =#REF! -> #REF! | I26: Use
A27: 24 | B27: Pikachu | D27: 15 | F27: 40 | H27: or | I27: Item
A28: 25 | B28: Raichu | D28: =IP!B2 -> #VALUE! | F28: =IP!B2 -> #VALUE! | I28: =IP!B5 -> #VALUE!
A29: 26 | B29: Sandshrew | C29: =#REF! -> #REF! | D29: Level | E29: =#REF! -> #REF!
A30: 27 | B30: Sandslash | D30: 22
D31: =IP!B2 -> #VALUE!
A32: 28 | B32: Nidoran♀ | C32: =#REF! -> #REF! | D32: Level | E32: =#REF! -> #REF! | F32: Level | G32: =#REF! -> #REF!
A33: 29 | B33: Nidorina | D33: 21 | F33: 42
A34: 30 | B34: Nidoqueen | D34: =IP!B2 -> #VALUE! | F34: =IP!B2 -> #VALUE!
A35: 31 | B35: Nidoran♂ | C35: =#REF! -> #REF! | D35: Level | E35: =#REF! -> #REF! | F35: Level | G35: =#REF! -> #REF!
A36: 32 | B36: Nidorino | D36: 21 | F36: 42
A37: 33 | B37: Nidoking | D37: =IP!B2 -> #VALUE! | F37: =IP!B2 -> #VALUE!
A38: 34 | B38: Cleffa | C38: =#REF! -> #REF! | D38: Level | E38: =#REF! -> #REF! | F38: Level | G38: =#REF! -> #REF! | I38: Use
A39: 35 | B39: Clefairy | D39: 15 | F39: 39 | H39: or | I39: Item
A40: 36 | B40: Clefable | D40: =IP!B2 -> #VALUE! | F40: =IP!B2 -> #VALUE! | I40: =IP!B7 -> #VALUE!
...

Sheet Learnset
A1: Dex Number | B1: Name | C1: Level | D1: Move | E1: Level | F1: Move | G1: Level | H1: Move | I1: Level | J1: Move | K1: Level | L1: Move | M1: Level | N1: Move | O1: Level | P1: Move | Q1: Level | R1: Move | S1: Level | T1: Move | U1: Level | V1: Move | W1: Level | X1: Move | Y1: Level | Z1: Move | AA1: Level | AB1: Move | AC1: Level | AD1: Move | AE1: Level | AF1: Move | AG1: Level | AH1: Move | AI1: Level | AJ1: Move | AK1: Level | AL1: Move | AM1: Level | AN1: Move | AO1: Level | AP1: Move | AQ1: Level
A2: 1 | B2: Bulbasaur
A3: 2 | B3: Ivysaur
A4: 3 | B4: Venusaur
A5: 4 | B5: Charmander
A6: 5 | B6: Charmeleon
A7: 6 | B7: Charizard
A8: 7 | B8: Squirtle
A9: 8 | B9: Wartortle
A10: 9 | B10: Blastoise
A11: 10 | B11: Caterpie
A12: 11 | B12: Metapod
A13: 12 | B13: Butterfree
... A504: 503 | B504: Arceus
A505: 450 - 1 | B505: Wormadam Sandy
A506: 450 - 2 | B506: Wormadam Trash
A507: 459 - 1 | B507: Shellos East
A508: 460 - 1 | B508: Gastrodon East

Sheet Boss Fights
A1: Location | B1: Trainer | C1: Pokémon | D1: Level | E1: Ability | F1: Item | G1: Nature | H1: IVs | I1: EVs | J1: Move 1 | K1: Move 2 | L1: Move 3 | M1: Move 4 | O1: Header Palette generated by PokémonPallete.com
B2: Name | C2: Pokémon 1 | D2: ??? | E2: Ability | F2: Item | G2: Hardy | H2: 0 | I2: 0 | J2: Splash | K2: Splash | L2: Splash | M2: Splash
B3: Role | C3: Pokémon 2 | D3: ??? | E3: Ability | F3: Item | G3: Hardy | H3: 0 | I3: 0 | J3: Splash | K3: Splash | L3: Splash | M3: Splash
C4: Pokémon 2 | D4: ??? | E4: Ability | F4: Item | G4: Hardy | H4: 0 | I4: 0 | J4: Splash | K4: Splash | L4: Splash | M4: Splash
C5: Pokémon 4 | D5: ??? | E5: Ability | F5: Item | G5: Hardy | H5: 0 | I5: 0 | J5: Splash | K5: Splash | L5: Splash | M5: Splash
C6: Pokémon 5 | D6: ??? | E6: Ability | F6: Item | G6: Hardy | H6: 0 | I6: 0 | J6: Splash | K6: Splash | L6: Splash | M6: Splash
C7: Pokémon 6 | D7: ??? | E7: Ability | F7: Item | G7: Hardy | H7: 0 | I7: 0 | J7: Splash | K7: Splash | L7: Splash | M7: Splash
B8: Falkner | C8: Pokémon 1 | D8: ??? | E8: Ability | F8: Item | G8: Hardy | H8: 0 | I8: 0 | J8: Splash | K8: Splash | L8: Splash | M8: Splash
B9: Gym Leader | C9: Pokémon 2 | D9: ??? | E9: Ability | F9: Item | G9: Hardy | H9: 0 | I9: 0 | J9: Splash | K9: Splash | L9: Splash | M9: Splash
C10: Pokémon 3 | D10: ??? | E10: Ability | F10: Item | G10: Hardy | H10: 0 | I10: 0 | J10: Splash | K10: Splash | L10: Splash | M10: Splash
C11: Pokémon 4 | D11: ??? | E11: Ability | F11: Item | G11: Hardy | H11: 0 | I11: 0 | J11: Splash | K11: Splash | L11: Splash | M11: Splash
C12: Pokémon 5 | D12: ??? | E12: Ability | F12: Item | G12: Hardy | H12: 0 | I12: 0 | J12: Splash | K12: Splash | L12: Splash | M12: Splash
C13: Pokémon 6 | D13: ??? | E13: Ability | F13: Item | G13: Hardy | H13: 0 | I13: 0 | J13: Splash | K13: Splash | L13: Splash | M13: Splash
A14: Perma drizzle | B14: Bugsy | C14: Scyther | D14: ??? | E14: Technician | F14: Item | G14: Hardy | H14: 0 | I14: 0 | J14: U-Turn | K14: Brick Break
A15: "bloody water leak in my gym" and the town is perma raining | B15: Gym Leader | C15: Forretress | D15: ??? | E15: Heatproof | F15: Item | G15: Hardy | H15: 0 | I15: 0 | J15: Gyro Ball | K15: Ancient Power | L15: Pain Split | M15: Stealth Rock
C16: Butterfree | D16: ??? | E16: Compound Eyes | F16: Item | G16: Hardy | H16: 0 | I16: 0 | J16: Psywave | K16: Air Slash | L16: Quiver Dance | M16: Sleep Powder
C17: Pokémon 4 | D17: ??? | E17: Ability | F17: Item | G17: Hardy | H17: 0 | I17: 0 | J17: Splash | K17: Splash | L17: Splash | M17: Splash
C18: Pokémon 5 | D18: ??? | E18: Ability | F18: Item | G18: Hardy | H18: 0 | I18: 0 | J18: Splash | K18: Splash | L18: Splash | M18: Splash
C19: Pokémon 6 | D19: ??? | E19: Ability | F19: Item | G19: Hardy | H19: 0 | I19: 0 | J19: Splash | K19: Splash | L19: Splash | M19: Splash
B20: Whitney | C20: Pokémon 1 | D20: ??? | E20: Ability | F20: Item | G20: Hardy | H20: 0 | I20: 0 | J20: Splash | K20: Splash | L20: Splash | M20: Splash
B21: Gym Leader | C21: Pokémon 2 | D21: ??? | E21: Ability | F21: Item | G21: Hardy | H21: 0 | I21: 0 | J21: Splash | K21: Splash | L21: Splash | M21: Splash
C22: Pokémon 3 | D22: ??? | E22: Ability | F22: Item | G22: Hardy | H22: 0 | I22: 0 | J22: Splash | K22: Splash | L22: Splash | M22: Splash
C23: Pokémon 4 | D23: ??? | E23: Ability | F23: Item | G23: Hardy | H23: 0 | I23: 0 | J23: Splash | K23: Splash | L23: Splash | M23: Splash
C24: Pokémon 5 | D24: ??? | E24: Ability | F24: Item | G24: Hardy | H24: 0 | I24: 0 | J24: Splash | K24: Splash | L24: Splash | M24: Splash
C25: Pokémon 6 | D25: ??? | E25: Ability | F25: Item | G25: Hardy | H25: 0 | I25: 0 | J25: Splash | K25: Splash | L25: Splash | M25: Splash
B26: Morty | C26: Pokémon 1 | D26: ??? | E26: Ability | F26: Item | G26: Hardy | H26: 0 | I26: 0 | J26: Splash | K26: Splash | L26: Splash | M26: Splash
B27: Gym Leader | C27: Pokémon 2 | D27: ??? | E27: Ability | F27: Item | G27: Hardy | H27: 0 | I27: 0 | J27: Splash | K27: Splash | L27: Splash | M27: Splash
C28: Pokémon 3 | D28: ??? | E28: Ability | F28: Item | G28: Hardy | H28: 0 | I28: 0 | J28: Splash | K28: Splash | L28: Splash | M28: Splash
C29: Pokémon 4 | D29: ??? | E29: Ability | F29: Item | G29: Hardy | H29: 0 | I29: 0 | J29: Splash | K29: Splash | L29: Splash | M29: Splash
C30: Pokémon 5 | D30: ??? | E30: Ability | F30: Item | G30: Hardy | H30: 0 | I30: 0 | J30: Splash | K30: Splash | L30: Splash | M30: Splash
C31: Pokémon 6 | D31: ??? | E31: Ability | F31: Item | G31: Hardy | H31: 0 | I31: 0 | J31: Splash | K31: Splash | L31: Splash | M31: Splash
B32: Chuck | C32: Pokémon 1 | D32: ??? | E32: Ability | F32: Item | G32: Hardy | H32: 0 | I32: 0 | J32: Splash | K32: Splash | L32: Splash | M32: Splash
B33: Gym Leader | C33: Pokémon 2 | D33: ??? | E33: Ability | F33: Item | G33: Hardy | H33: 0 | I33: 0 | J33: Splash | K33: Splash | L33: Splash | M33: Splash
C34: Pokémon 3 | D34: ??? | E34: Ability | F34: Item | G34: Hardy | H34: 0 | I34: 0 | J34: Splash | K34: Splash | L34: Splash | M34: Splash
C35: Pokémon 4 | D35: ??? | E35: Ability | F35: Item | G35: Hardy | H35: 0 | I35: 0 | J35: Splash | K35: Splash | L35: Splash | M35: Splash
C36: Pokémon 5 | D36: ??? | E36: Ability | F36: Item | G36: Hardy | H36: 0 | I36: 0 | J36: Splash | K36: Splash | L36: Splash | M36: Splash
C37: Pokémon 6 | D37: ??? | E37: Ability | F37: Item | G37: Hardy | H37: 0 | I37: 0 | J37: Splash | K37: Splash | L37: Splash | M37: Splash
B38: Jasmine | C38: Tangrowth | D38: ??? | E38: Thick Fat | F38: Chople Berry | G38: Bold | H38: 0 | I38: 0 | J38: Giga Drain | K38: Knock Off | L38: Leech Seed | M38: Sticky Web
B39: Gym Leader | C39: Jirachi | D39: ??? | E39: Serence Grace | F39: Leftovers | G39: Jolly | H39: 0 | I39: 0 | J39: Iron Head | K39: Zen Headbutt | L39: Body Slam | M39: Wish
C40: Empoleon | D40: ??? | E40: Queenly Majesty | F40: Air Balloon | G40: Hasty | H40: 0 | I40: 0 | J40: Scald | K40: Knock Off | L40: Flip Turn | M40: Roost
...

Sheet Trainer Fights
A1: Location | B1: Trainer | C1: Pokémon | D1: Level | E1: Ability | F1: Item | G1: Nature | H1: IVs | I1: EVs | J1: Move 1 | K1: Move 2 | L1: Move 3 | M1: Move 4 | P1: Header Palette generated by PokémonPallete.com
B2: Name | C2: Pokémon 1 | D2: ??? | E2: Ability | F2: Item | G2: Hardy | H2: 0 | I2: 0 | J2: Splash | K2: Splash | L2: Splash | M2: Splash
C3: Pokémon 2 | D3: ??? | E3: Ability | F3: Item | G3: Hardy | H3: 0 | I3: 0 | J3: Splash | K3: Splash | L3: Splash | M3: Splash
C4: Pokémon 2 | D4: ??? | E4: Ability | F4: Item | G4: Hardy | H4: 0 | I4: 0 | J4: Splash | K4: Splash | L4: Splash | M4: Splash
C5: Pokémon 4 | D5: ??? | E5: Ability | F5: Item | G5: Hardy | H5: 0 | I5: 0 | J5: Splash | K5: Splash | L5: Splash | M5: Splash
C6: Pokémon 5 | D6: ??? | E6: Ability | F6: Item | G6: Hardy | H6: 0 | I6: 0 | J6: Splash | K6: Splash | L6: Splash | M6: Splash
C7: Pokémon 6 | D7: ??? | E7: Ability | F7: Item | G7: Hardy | H7: 0 | I7: 0 | J7: Splash | K7: Splash | L7: Splash | M7: Splash
B8: Name | C8: Pokémon 1 | D8: ??? | E8: Ability | F8: Item | G8: Hardy | H8: 0 | I8: 0 | J8: Splash | K8: Splash | L8: Splash | M8: Splash
C9: Pokémon 2 | D9: ??? | E9: Ability | F9: Item | G9: Hardy | H9: 0 | I9: 0 | J9: Splash | K9: Splash | L9: Splash | M9: Splash
C10: Pokémon 2 | D10: ??? | E10: Ability | F10: Item | G10: Hardy | H10: 0 | I10: 0 | J10: Splash | K10: Splash | L10: Splash | M10: Splash
C11: Pokémon 4 | D11: ??? | E11: Ability | F11: Item | G11: Hardy | H11: 0 | I11: 0 | J11: Splash | K11: Splash | L11: Splash | M11: Splash
C12: Pokémon 5 | D12: ??? | E12: Ability | F12: Item | G12: Hardy | H12: 0 | I12: 0 | J12: Splash | K12: Splash | L12: Splash | M12: Splash
C13: Pokémon 6 | D13: ??? | E13: Ability | F13: Item | G13: Hardy | H13: 0 | I13: 0 | J13: Splash | K13: Splash | L13: Splash | M13: Splash
B14: Name | C14: Pokémon 1 | D14: ??? | E14: Ability | F14: Item | G14: Hardy | H14: 0 | I14: 0 | J14: Splash | K14: Splash | L14: Splash | M14: Splash
C15: Pokémon 2 | D15: ??? | E15: Ability | F15: Item | G15: Hardy | H15: 0 | I15: 0 | J15: Splash | K15: Splash | L15: Splash | M15: Splash
C16: Pokémon 2 | D16: ??? | E16: Ability | F16: Item | G16: Hardy | H16: 0 | I16: 0 | J16: Splash | K16: Splash | L16: Splash | M16: Splash
C17: Pokémon 4 | D17: ??? | E17: Ability | F17: Item | G17: Hardy | H17: 0 | I17: 0 | J17: Splash | K17: Splash | L17: Splash | M17: Splash
C18: Pokémon 5 | D18: ??? | E18: Ability | F18: Item | G18: Hardy | H18: 0 | I18: 0 | J18: Splash | K18: Splash | L18: Splash | M18: Splash
C19: Pokémon 6 | D19: ??? | E19: Ability | F19: Item | G19: Hardy | H19: 0 | I19: 0 | J19: Splash | K19: Splash | L19: Splash | M19: Splash
B20: Name | C20: Pokémon 1 | D20: ??? | E20: Ability | F20: Item | G20: Hardy | H20: 0 | I20: 0 | J20: Splash | K20: Splash | L20: Splash | M20: Splash
C21: Pokémon 2 | D21: ??? | E21: Ability | F21: Item | G21: Hardy | H21: 0 | I21: 0 | J21: Splash | K21: Splash | L21: Splash | M21: Splash
C22: Pokémon 2 | D22: ??? | E22: Ability | F22: Item | G22: Hardy | H22: 0 | I22: 0 | J22: Splash | K22: Splash | L22: Splash | M22: Splash
C23: Pokémon 4 | D23: ??? | E23: Ability | F23: Item | G23: Hardy | H23: 0 | I23: 0 | J23: Splash | K23: Splash | L23: Splash | M23: Splash
C24: Pokémon 5 | D24: ??? | E24: Ability | F24: Item | G24: Hardy | H24: 0 | I24: 0 | J24: Splash | K24: Splash | L24: Splash | M24: Splash
C25: Pokémon 6 | D25: ??? | E25: Ability | F25: Item | G25: Hardy | H25: 0 | I25: 0 | J25: Splash | K25: Splash | L25: Splash | M25: Splash
B26: Name | C26: Pokémon 1 | D26: ??? | E26: Ability | F26: Item | G26: Hardy | H26: 0 | I26: 0 | J26: Splash | K26: Splash | L26: Splash | M26: Splash
C27: Pokémon 2 | D27: ??? | E27: Ability | F27: Item | G27: Hardy | H27: 0 | I27: 0 | J27: Splash | K27: Splash | L27: Splash | M27: Splash
C28: Pokémon 2 | D28: ??? | E28: Ability | F28: Item | G28: Hardy | H28: 0 | I28: 0 | J28: Splash | K28: Splash | L28: Splash | M28: Splash
C29: Pokémon 4 | D29: ??? | E29: Ability | F29: Item | G29: Hardy | H29: 0 | I29: 0 | J29: Splash | K29: Splash | L29: Splash | M29: Splash
C30: Pokémon 5 | D30: ??? | E30: Ability | F30: Item | G30: Hardy | H30: 0 | I30: 0 | J30: Splash | K30: Splash | L30: Splash | M30: Splash
C31: Pokémon 6 | D31: ??? | E31: Ability | F31: Item | G31: Hardy | H31: 0 | I31: 0 | J31: Splash | K31: Splash | L31: Splash | M31: Splash
B32: Name | C32: Pokémon 1 | D32: ??? | E32: Ability | F32: Item | G32: Hardy | H32: 0 | I32: 0 | J32: Splash | K32: Splash | L32: Splash | M32: Splash
C33: Pokémon 2 | D33: ??? | E33: Ability | F33: Item | G33: Hardy | H33: 0 | I33: 0 | J33: Splash | K33: Splash | L33: Splash | M33: Splash
C34: Pokémon 2 | D34: ??? | E34: Ability | F34: Item | G34: Hardy | H34: 0 | I34: 0 | J34: Splash | K34: Splash | L34: Splash | M34: Splash
C35: Pokémon 4 | D35: ??? | E35: Ability | F35: Item | G35: Hardy | H35: 0 | I35: 0 | J35: Splash | K35: Splash | L35: Splash | M35: Splash
C36: Pokémon 5 | D36: ??? | E36: Ability | F36: Item | G36: Hardy | H36: 0 | I36: 0 | J36: Splash | K36: Splash | L36: Splash | M36: Splash
C37: Pokémon 6 | D37: ??? | E37: Ability | F37: Item | G37: Hardy | H37: 0 | I37: 0 | J37: Splash | K37: Splash | L37: Splash | M37: Splash
B38: Name | C38: Rhyperior | D38: ??? | E38: Rock Head | F38: Rindo Berry | G38: Adamant | H38: 0 | I38: 0 | J38: Head Smash | K38: Earthquake | L38: Submission | M38: Megahorn
B39: Double | C39: Gastrodon East | D39: ??? | E39: Storm Drain | F39: Air Balloon | G39: Calm | H39: 0 | I39: 0 | J39: Sludge Wave | K39: Muddy Water | L39: Infestation | M39: Clear Smog
C40: Gastrodon West | D40: ??? | E40: Storm Drain | F40: Air Balloon | G40: Calm | H40: 0 | I40: 0 | J40: Surf | K40: Earth Power | L40: Ice Beam | M40: Pain Split
...

Sheet Encounters
A1: Name | B1: Area | C1: Mon 1 | D1: Chance | E1: Mon 2 | F1: Chance | G1: Mon 3 | H1: Chance | I1: Mon 4 | J1: Chance | K1: Mon 5 | L1: Chance | M1: Mon 6 | N1: Chance | O1: Mon 7 | P1: Chance | Q1: Mon 8 | R1: Chance | S1: Mon 9 | T1: Chance | U1: Mon 10 | V1: Chance | W1: Mon 11 | X1: Chance | Y1: Mon 12

Sheet Moves
A1: Name | B1: Type | C1: Category | D1: Power | E1: Effect | F1: Accuracy | G1: PP | H1: Target | I1: Other | J1: What changed | K1: Header Palette generated by PokémonPallete.com | M1: Name | N1: Type | O1: Category | P1: Power | Q1: Effect | R1: Accuracy | S1: PP | T1: Target
A2: Egg Bomb | B2: Grass | C2: Special | D2: 100 | E2: N/A | F2: 100 | G2: 10 | H2: Single | J2: Special, Grass, 100 acc
A3: Barrage | B3: Psychic | C3: Special | D3: 20 | E3: Hit 3 times, Power+ per hit | F3: 100 | G3: 10 | H3: Single | I3: Now called "Psychic Barrage". Works like Triple Axel. Now Smart in contests. | J3: Rework
A4: X-Scissor | B4: Bug | C4: Physical | D4: 90 | E4: N/A | F4: 100 | G4: 15 | H4: Single | I4: maybe 85 if it too strong | J4: 10+ power | K4: Was gonna use Smeargle's but it was a bit bland for me as you can see
A5: Snarl | B5: Dark | C5: Special | D5: 60 | E5: Lowers Foe's SPATK | F5: 100 | G5: 15 | H5: Both | I5: a dark special attack that isnt dark pulse is neat as I want to reduce the amount of overall coverage to nerf choice users | J5: -5 power, 100 acc
A6: Surf | B6: Water | C6: Special | D6: 70 | E6: N/A | F6: 100 | G6: 15 | H6: Both | I6: I hate hydro pump because surf is already so powerful + hitting both is insane for such a solid defensive type | J6: -20 power | K6: Bold moves mean they are new moves
A7: Ice Beam | B7: Ice | C7: Special | D7: 85 | E7: Chance of Freeze | F7: 100 | G7: 10 | H7: Single | I7: the age of special coverage doing insane coverage has come to an end | J7: -5 power
A8: Thunderbolt | B8: Electric | C8: Special | D8: 85 | E8: Chance of Para | F8: 100 | G8: 15 | H8: Single | I8: I always felt like because of these moves, special attackers had a much bigger advantage over physical attackers | J8: -5 power
A9: Flamethrower | B9: Fire | C9: Special | D9: 85 | E9: Chance of Burn | F9: 100 | G9: 15 | H9: Single | I9: I also feel like ice, water and fire types are underappreciated for their stab cause the coverage is just so good | J9: -5 power
A10: Psychic | B10: Psychic | C10: Special | D10: 85 | E10: May Enemy SPD- | F10: 100 | G10: 10 | H10: Single | I10: Im open to reverting these, psychic is probably the most likely to revert anyway | J10: -5 power
A11: Constrict | B11: Grass | C11: Physical | D11: 45 | E11: -SPE | F11: 100 | G11: 30 | H11: Single | I11: neat coverage + variance | J11: Grass, -5 pp
